{"frames":[{"func":"nn_model %>% fit(bag_of_words_train_features, bag_of_words_train_target, \n    epochs = 30, batch_size = 5, shuffle = TRUE)","file":"","line_number":0,"end_line_number":0,"character_number":0,"end_character_number":0},{"func":"fit(., bag_of_words_train_features, bag_of_words_train_target, \n    epochs = 30, batch_size = 5, shuffle = TRUE)","file":"","line_number":0,"end_line_number":0,"character_number":0,"end_character_number":0},{"func":"fit.keras.engine.training.Model(., bag_of_words_train_features, \n    bag_of_words_train_target, epochs = 30, batch_size = 5, shuffle = TRUE)","file":"","line_number":0,"end_line_number":0,"character_number":0,"end_character_number":0},{"func":"do.call(object$fit, args)","file":"","line_number":0,"end_line_number":0,"character_number":0,"end_character_number":0},{"func":"(structure(function (x = NULL, y = NULL, batch_size = NULL, epochs = 1L, \n    verbose = \"auto\", callbacks = NULL, validation_split = 0, \n    validation_data = NULL, shuffle = TRUE, class_weight = NULL, \n    sample_weight = NULL, initial_epoch = 0L, steps_per_epoch = NULL,  ...","file":"","line_number":0,"end_line_number":0,"character_number":0,"end_character_number":0},{"func":"stop(<environment>)","file":"","line_number":0,"end_line_number":0,"character_number":0,"end_character_number":0}],"message":"Error in py_call_impl(callable, call_args$unnamed, call_args$named) : \n  ValueError: in user code:\n\n<...truncated...>y\", line 277, in __call__\n        loss_value = loss_obj(y_t, y_p, sample_weight=sw)\n    File \"C:\\Users\\natal\\ANACON~1\\envs\\RMINIC~1\\lib\\site-packages\\keras\\src\\losses.py\", line 143, in __call__\n        losses = call_fn(y_true, y_pred)\n    File \"C:\\Users\\natal\\ANACON~1\\envs\\RMINIC~1\\lib\\site-packages\\keras\\src\\losses.py\", line 270, in call  **\n        return ag_fn(y_true, y_pred, **self._fn_kwargs)\n    File \"C:\\Users\\natal\\ANACON~1\\envs\\RMINIC~1\\lib\\site-packages\\keras\\src\\losses.py\", line 2221, in categorical_crossentropy\n        return backend.categorical_crossentropy(\n    File \"C:\\Users\\natal\\ANACON~1\\envs\\RMINIC~1\\lib\\site-packages\\keras\\src\\backend.py\", line 5575, in categorical_crossentropy\n        target.shape.assert_is_compatible_with(output.shape)\n\n    ValueError: Shapes (5, 4, 2) and (5, 4) are incompatible\n\n\u001B[90mRun \u001B]8;;rstudio:run:reticulate::py_last_error()\u0007`reticulate::py_last_error()`\u001B]8;;\u0007 for details.\u001B[39m\n"}